<?xml version="1.0"?>
<robot xmlns:xacro="http://www.ros.org/wiki/xacro" name="rover">
<xacro:property name="c1"       value="0.083"/>
<xacro:property name="c2"       value="0.5"/>
<xacro:property name="mass"     value="1"/>
<xacro:property name="width"    value="0.8"/>
<xacro:property name="height"   value="0.1"/>
<xacro:property name="depth"    value="0.7 "/>
<xacro:property name="radius"   value="0.15 "/>

<!-- COLORS -->
<material name="Blue">
  <color rgba=" 1 1 0 1"/>
</material>

<material name="Red">
  <color rgba="0 0 0 1"/>
</material>
<!-- BASE LINK AND JOINT -->
<!-- BASE LINK AND JOINT -->

  <link name="base_footprint"/> 

  <link name="base_link">   
    <visual>
      <origin xyz="0 0 0" rpy="0.0 0.0 0.0"/>
      <geometry>
        <box size="0.227 0.16 0.047" />
      </geometry>
      <material name="Blue">
        <color rgba="0.25 0.25 0.25 1.0"/>
      </material>
    </visual>
    <collision>
      <origin xyz="0 0 0" rpy="0.0 0.0 0.0"/>
      <geometry>
        <box size="0.8 0.7 0.1" />
      </geometry>
    </collision>   
    <inertial>
      <mass value="0.5"/>
      <origin xyz="0.0 0.0 0" rpy="0.0 0.0 0.0"/>
      <inertia  ixx="${c1 * mass * (height * height + depth * depth)}" ixy="0.0" ixz="0.0" 
                iyy="${c1 * mass * (height * height + depth * depth)}" iyz="0.0" 
                izz="${c1 * mass * (height * height + depth * depth)}"/>
    </inertial>
  </link>

<joint name="base_joint" type="fixed">
		<origin xyz="0 0 0.135" rpy="0 0 0" />
		<parent link="base_footprint"/>
		<child link="base_link" />
	</joint>


<!--WHEEL LINKS AND JOINT -->

<xacro:macro name="wheel" params="name x y">
    <link name="wheel_${name}_link">       
        <inertial>
            <origin xyz="0 0 0" rpy="0 0 0"/>
            <mass value="0.25"/>
            <inertia  ixx="${c2 * mass * (radius*radius)}" ixy="0.0" ixz="0.0" 
                      iyy="${c2 * mass * (radius*radius)}" iyz="0.0" 
                      izz="${c2 * mass * (radius*radius)}"/>
        </inertial>
        <visual name="wheel_${name}_visual">
            <origin xyz="0 0 0" rpy="1.57 0.0 0.0"/>
            <geometry>
              <cylinder radius="0.04" length="0.03"/>            
            </geometry>
            <material name="Red">
              <color rgba="0 0.7 0.7 1.0"/>
            </material>
        </visual>       
        <collision>
            <origin xyz="0 0 0" rpy="1.57 0.0 0.0"/>
            <geometry>
              <cylinder radius="0.04" length="0.03"/>            
            </geometry>
        </collision>
    </link>
    <joint name="wheel_${name}_joint" type="continuous">
        <origin xyz="${x} ${y} 0" rpy="0 0 0"/>
        <parent link="base_link"/>
        <child link="wheel_${name}_link"/>
        <axis xyz="0 1 0"/>
        <limit velocity="100.0" effort="1000.0" />
        <dynamics damping="1.0" friction="1.0"/>
    </joint>
</xacro:macro>


<xacro:wheel name="front_left"  x="0.1135" y =" 0.095"/>
<xacro:wheel name="rear_left" x="-0.1135" y =" 0.095"/>
<xacro:wheel name="rear_right"  x="-0.1135" y =" -0.095"/>
<xacro:wheel name="front_right"   x="0.1135" y =" -0.095"/>

</robot>